<?xml version='1.0'?>
<sdf version="1.6">
<model name="multicopter">

	<!-- ** Links Definitions ** -->
	<!-- * Base Definitions * -->
	<link name="base_link">
		<!-- Position -->
		<pose>0 0 0.35 0 -0 0</pose>
		<!-- Inertia -->
		<inertial>
			<pose frame=>0 0 0 0 -0 0</pose>
			<mass> 8.5</mass>
			<inertia>
				<ixx>1.38</ixx>
				<ixy>0</ixy>
				<ixz>0</ixz>
				<iyy>0.83</iyy>
				<iyz>0</iyz>
				<izz>2.16</izz>
			</inertia>
		</inertial>		
		<!-- collision -->
		<collision name="base_link_colision">
			<pose frame=>0 0 0 0 0 0</pose>
			<geometry>
				<box>
					<size> 0.45 2.5 0.30 </size>
				</box>
			</geometry>
			<surface>
				<contact>
					<ode>
						<min_depth>0.001</min_depth>
						<max_vel>0</max_vel>
					</ode>
				</contact>
				<friction>
					<ode/>
				</friction>
			</surface>
		</collision>
		
		<!-- Visual -->
				<visual name="base_link_column_right_visual">
			<pose frame=>0 -0.475 0.01 0 0 0</pose>
			<geometry>
				<box>
					<size> 0.74 0.03 0.03 </size>
	 			</box>
			</geometry>
			<material>
				<script>
					<name>Gazebo/Grey</name>
					<uri>file://media/materials/scripts/gazebo.material</uri>
				</script>
				<shader type='pixel'/>
          			<emissive>0 0 0 1</emissive>
			</material>
			<transparency>0</transparency>
        		<cast_shadows>1</cast_shadows>
		</visual>		
		<visual name="base_link_visual">
			<pose frame=>0.17 0 0.02 0 0 1.5708</pose>
			<geometry>
				<mesh>
					<scale>0.001 0.001 0.001</scale>
					<uri>model://DACAR/meshes/untitled.stl</uri>
				</mesh>
			</geometry>
			<material>
				<script>
					<name>Gazebo/White</name>
					<uri>__default__</uri>
				</script>
				<shader type='pixel'/>
          			<emissive>0 0 0 1</emissive>
			</material>
			<transparency>0</transparency>
        		<cast_shadows>1</cast_shadows>
		</visual>
		<visual name="base_link_column_left_visual">
			<pose frame=>0 0.475 0.01 0 0 0</pose>
			<geometry>
				<box>
					<size> 0.74 0.03 0.03 </size>
	 			</box>
			</geometry>
			<material>
				<script>
					<name>Gazebo/Grey</name>
					<uri>file://media/materials/scripts/gazebo.material</uri>
				</script>
				<shader type='pixel'/>
          			<emissive>0 0 0 1</emissive>
			</material>
			<transparency>0</transparency>
        		<cast_shadows>1</cast_shadows>
		</visual>				
		<gravity>1</gravity>
      		<velocity_decay/>
	</link>


		
	<link name="/imu_link">
		<!-- Position -->
		<pose>0 0 0.35 0 -0 0</pose>
		<!-- Inertia -->
		<inertial>
			<pose frame=>0 0 0 0 -0 0</pose>
			<mass> 0.015</mass>
			<inertia>
				<ixx>1.0e-05</ixx>
				<ixy>0</ixy>
				<ixz>0</ixz>
				<iyy>1.0e-05</iyy>
				<iyz>0</iyz>
				<izz>1.0e-05</izz>
			</inertia>
		</inertial>		
	</link>
	
	<joint name="imu_joint" type="revolute">
		<child>/imu_link</child>
		<parent>base_link</parent>
		<pose frame=>0 0 0 0 0 0</pose>
		<axis>
			<xyz>1 0 0</xyz>
			<limit>
				<lower>0</lower>
				<upper>0</upper>
			</limit>
			<dynamics>
				<spring_reference>0</spring_reference>
				<spring_stiffness>0</spring_stiffness>
				<damping>0</damping>
			</dynamics>
			<use_parent_model_frame>1</use_parent_model_frame>
		</axis>
		
	</joint>	
	
	<link name='right_elevon'>
	        <!-- Position -->
	        <pose frame=''>-0.124720 -0.829266 0.396834 -0.093490 0.001436 0.016471</pose>
		<!-- Inertia -->
		<inertial>
			<pose frame=>0 0 0 0 -0 0</pose>
			<mass> 1.0e-11</mass>
			<inertia>
				<ixx>1.0e-09</ixx>
				<ixy>0</ixy>
				<ixz>0</ixz>
				<iyy>1.0e-09</iyy>
				<iyz>0</iyz>
				<izz>1.0e-09</izz>
			</inertia>
		</inertial>		                                               
		<!-- collision -->
		<collision name="right_elevon_colision">
			<laser_retro>0</laser_retro>
			<max_contacts>10</max_contacts>
			<pose frame=>0 0 0 0 0 0</pose>
			<geometry>
				<box>
					<size> 0.058634 0.391614 0.000598 </size>
				</box>
			</geometry>
			<surface>
				<friction>
					<ode>
						<mu>1</mu>
						<mu2>1</mu2>
						<fdir1>0 0 0</fdir1>
						<slip1>0</slip1>
						<slip2>0</slip2>
					</ode>
					<torsional>
						<coefficient>1</coefficient>
						<patch_radius>0</patch_radius>
						<surface_radius>0</surface_radius>
						<use_patch_radius>1</use_patch_radius>
						<ode>
							<slip>0</slip>
						</ode>
					</torsional>
				</friction>
				<bounce>
					<restitution_coefficient>0</restitution_coefficient>
					<threshold>1e+06</threshold>
				</bounce>
				<contact>
					<collide_without_contact>0</collide_without_contact>
					<collide_without_contact_bitmask>1</collide_without_contact_bitmask>
					<collide_bitmask>1</collide_bitmask>
					<ode>
						<soft_cfm>0</soft_cfm>
						<soft_erp>0.2</soft_erp>
						<kp>1e+13</kp>
						<kd>1</kd>
						<max_vel>0.01</max_vel>
						<min_depth>0</min_depth>
					</ode>
					<bullet>
						<split_impulse>1</split_impulse>
						<split_impulse_penetration_threshold>-0.01</split_impulse_penetration_threshold>
						<soft_cfm>0</soft_cfm>
						<soft_erp>0.2</soft_erp>
						<kp>1e+13</kp>
						<kd>1</kd>
					</bullet>
				</contact>
			</surface>
		</collision>
		<!-- Visual -->
		<visual name="right_elevon_visual">
			<pose frame=>0 0 0 0 0 0</pose>
			<geometry>
				<box>
					<size> 0.058634 0.582127 0.000598 </size>
	 			</box>
			</geometry>
			<material>
				<script>
					<name>Gazebo/Grey</name>
					<uri>file://media/materials/scripts/gazebo.material</uri>
				</script>
				<shader type='pixel'/>
          			<emissive>0 0 0 1</emissive>
			</material>
			<transparency>0</transparency>
        		<cast_shadows>1</cast_shadows>
		</visual>	</link>
	<joint name="right_elevon_joint" type="revolute">
		<child>right_elevon</child>
		<parent>base_link</parent>
		<pose frame=>0.025 0.28 -0.005 0 0 0</pose>
		<axis>
			<xyz>0 1 0</xyz>
			<limit>
				<lower>-0.25</lower>
				<upper>0.25</upper>
			</limit>
			<dynamics>
				<spring_reference>0</spring_reference>
				<spring_stiffness>0</spring_stiffness>
				<damping>2</damping>
			</dynamics>
			<use_parent_model_frame>1</use_parent_model_frame>
		</axis>
		<physics>
			<ode>	
          			<implicit_spring_damper>1</implicit_spring_damper>
        		</ode>
      		</physics>
	</joint>
	
	<link name='left_elevon'>
	        <!-- Position -->
	        <pose frame=''>-0.124720 0.829266 0.396834 0.093490 0.001436 -0.016471</pose>
		<!-- Inertia -->
		<inertial>
			<pose frame=>0 0 0 0 -0 0</pose>
			<mass> 1.0e-11</mass>
			<inertia>
				<ixx>1.0e-09</ixx>
				<ixy>0</ixy>
				<ixz>0</ixz>
				<iyy>1.0e-09</iyy>
				<iyz>0</iyz>
				<izz>1.0e-09</izz>
			</inertia>
		</inertial>
		<!-- collision -->
		<collision name="left_elevon_colision">
			<laser_retro>0</laser_retro>
			<max_contacts>10</max_contacts>
			<pose frame=>0 0 0 0 0 0</pose>
			<geometry>
				<box>
					<size> 0.058634 0.391614 0.000598 </size>
				</box>
			</geometry>
			<surface>
				<friction>
					<ode>
						<mu>1</mu>
						<mu2>1</mu2>
						<fdir1>0 0 0</fdir1>
						<slip1>0</slip1>
						<slip2>0</slip2>
					</ode>
					<torsional>
						<coefficient>1</coefficient>
						<patch_radius>0</patch_radius>
						<surface_radius>0</surface_radius>
						<use_patch_radius>1</use_patch_radius>
						<ode>
							<slip>0</slip>
						</ode>
					</torsional>
				</friction>
				<bounce>
					<restitution_coefficient>0</restitution_coefficient>
					<threshold>1e+06</threshold>
				</bounce>
				<contact>
					<collide_without_contact>0</collide_without_contact>
					<collide_without_contact_bitmask>1</collide_without_contact_bitmask>
					<collide_bitmask>1</collide_bitmask>
					<ode>
						<soft_cfm>0</soft_cfm>
						<soft_erp>0.2</soft_erp>
						<kp>1e+13</kp>
						<kd>1</kd>
						<max_vel>0.01</max_vel>
						<min_depth>0</min_depth>
					</ode>
					<bullet>
						<split_impulse>1</split_impulse>
						<split_impulse_penetration_threshold>-0.01</split_impulse_penetration_threshold>
						<soft_cfm>0</soft_cfm>
						<soft_erp>0.2</soft_erp>
						<kp>1e+13</kp>
						<kd>1</kd>
					</bullet>
				</contact>
			</surface>
		</collision>
		<!-- Visual -->
		<visual name="left_elevon_visual">
			<pose frame=>0 0 0 0 0 0</pose>
			<geometry>
				<box>
					<size> 0.058634 0.582127 0.000598 </size>
	 			</box>
			</geometry>
			<material>
				<script>
					<name>Gazebo/Grey</name>
					<uri>file://media/materials/scripts/gazebo.material</uri>
				</script>
				<shader type='pixel'/>
          			<emissive>0 0 0 1</emissive>
			</material>
			<transparency>0</transparency>
        		<cast_shadows>1</cast_shadows>
		</visual>	</link>
	<joint name="left_elevon_joint" type="revolute">
		<child>left_elevon</child>
		<parent>base_link</parent>
		<pose frame=>0.025 -0.28 -0.005 0 0 0</pose>
		<axis>
			<xyz>0 1 0</xyz>
			<limit>
				<lower>-0.25</lower>
				<upper>0.25</upper>
			</limit>
			<dynamics>
				<spring_reference>0</spring_reference>
				<spring_stiffness>0</spring_stiffness>
				<damping>2</damping>
			</dynamics>
			<use_parent_model_frame>1</use_parent_model_frame>
		</axis>
		<physics>
			<ode>	
          			<implicit_spring_damper>1</implicit_spring_damper>
        		</ode>
      		</physics>
	</joint>

	<link name='right_airbreak'>
	        <!-- Position -->
	        <pose frame=''>-0.132948 -0.232139 0.368761 0 -0.000108 0</pose>
		<!-- Inertia -->
		<inertial>
			<pose frame=>0 0 0 0 -0 0</pose>
			<mass> 1.0e-11</mass>
			<inertia>
				<ixx>1.0e-09</ixx>
				<ixy>0</ixy>
				<ixz>0</ixz>
				<iyy>1.0e-09</iyy>
				<iyz>0</iyz>
				<izz>1.0e-09</izz>
			</inertia>
		</inertial>
		<!-- collision -->
		<collision name="right_airbreak_colision">
			<laser_retro>0</laser_retro>
			<max_contacts>10</max_contacts>
			<pose frame=>0 0 0 0 0 0</pose>
			<geometry>
				<box>
					<size> 0.058634 0.391614 0.000598 </size>
				</box>
			</geometry>
			<surface>
				<friction>
					<ode>
						<mu>1</mu>
						<mu2>1</mu2>
						<fdir1>0 0 0</fdir1>
						<slip1>0</slip1>
						<slip2>0</slip2>
					</ode>
					<torsional>
						<coefficient>1</coefficient>
						<patch_radius>0</patch_radius>
						<surface_radius>0</surface_radius>
						<use_patch_radius>1</use_patch_radius>
						<ode>
							<slip>0</slip>
						</ode>
					</torsional>
				</friction>
				<bounce>
					<restitution_coefficient>0</restitution_coefficient>
					<threshold>1e+06</threshold>
				</bounce>
				<contact>
					<collide_without_contact>0</collide_without_contact>
					<collide_without_contact_bitmask>1</collide_without_contact_bitmask>
					<collide_bitmask>1</collide_bitmask>
					<ode>
						<soft_cfm>0</soft_cfm>
						<soft_erp>0.2</soft_erp>
						<kp>1e+13</kp>
						<kd>1</kd>
						<max_vel>0.01</max_vel>
						<min_depth>0</min_depth>
					</ode>
					<bullet>
						<split_impulse>1</split_impulse>
						<split_impulse_penetration_threshold>-0.01</split_impulse_penetration_threshold>
						<soft_cfm>0</soft_cfm>
						<soft_erp>0.2</soft_erp>
						<kp>1e+13</kp>
						<kd>1</kd>
					</bullet>
				</contact>
			</surface>
		</collision>
		<!-- Visual -->
		<visual name="right_airbreak_visual">
			<pose frame=>0 0 0 0 0 0</pose>
			<geometry>
				<box>
					<size> 0.058634 0.391614 0.000598 </size>
	 			</box>
			</geometry>
			<material>
				<script>
					<name>Gazebo/Grey</name>
					<uri>file://media/materials/scripts/gazebo.material</uri>
				</script>
				<shader type='pixel'/>
          			<emissive>0 0 0 1</emissive>
			</material>
			<transparency>0</transparency>
        		<cast_shadows>1</cast_shadows>
		</visual>	</link>
	<joint name="right_airbreak_joint" type="revolute">
		<child>right_airbreak</child>
		<parent>base_link</parent>
		<pose frame=>0.025 0.18 -0.005 0 0 0</pose>
		<axis>
			<xyz>0 1 0</xyz>
			<limit>
				<lower>-0.25</lower>
				<upper>0.25</upper>
			</limit>
			<dynamics>
				<spring_reference>0</spring_reference>
				<spring_stiffness>0</spring_stiffness>
				<damping>2</damping>
			</dynamics>
			<use_parent_model_frame>1</use_parent_model_frame>
		</axis>
		<physics>
			<ode>	
          			<implicit_spring_damper>1</implicit_spring_damper>
        		</ode>
      		</physics>
	</joint>	
	<link name='left_airbreak'>
	        <!-- Position -->
	        <pose frame=''>-0.132948 0.2354 0.368768 0 -5.4e-05 0</pose>
		<!-- Inertia -->
		<inertial>
			<pose frame=>0 0 0 0 -0 0</pose>
			<mass> 1.0e-11</mass>
			<inertia>
				<ixx>1.0e-09</ixx>
				<ixy>0</ixy>
				<ixz>0</ixz>
				<iyy>1.0e-09</iyy>
				<iyz>0</iyz>
				<izz>1.0e-09</izz>
			</inertia>
		</inertial>
		<!-- collision -->
		<collision name="left_airbreak_colision">
			<laser_retro>0</laser_retro>
			<max_contacts>10</max_contacts>
			<pose frame=>0 0 0 0 0 0</pose>
			<geometry>
				<box>
					<size> 0.058634 0.391614 0.000598 </size>
				</box>
			</geometry>
			<surface>
				<friction>
					<ode>
						<mu>1</mu>
						<mu2>1</mu2>
						<fdir1>0 0 0</fdir1>
						<slip1>0</slip1>
						<slip2>0</slip2>
					</ode>
					<torsional>
						<coefficient>1</coefficient>
						<patch_radius>0</patch_radius>
						<surface_radius>0</surface_radius>
						<use_patch_radius>1</use_patch_radius>
						<ode>
							<slip>0</slip>
						</ode>
					</torsional>
				</friction>
				<bounce>
					<restitution_coefficient>0</restitution_coefficient>
					<threshold>1e+06</threshold>
				</bounce>
				<contact>
					<collide_without_contact>0</collide_without_contact>
					<collide_without_contact_bitmask>1</collide_without_contact_bitmask>
					<collide_bitmask>1</collide_bitmask>
					<ode>
						<soft_cfm>0</soft_cfm>
						<soft_erp>0.2</soft_erp>
						<kp>1e+13</kp>
						<kd>1</kd>
						<max_vel>0.01</max_vel>
						<min_depth>0</min_depth>
					</ode>
					<bullet>
						<split_impulse>1</split_impulse>
						<split_impulse_penetration_threshold>-0.01</split_impulse_penetration_threshold>
						<soft_cfm>0</soft_cfm>
						<soft_erp>0.2</soft_erp>
						<kp>1e+13</kp>
						<kd>1</kd>
					</bullet>
				</contact>
			</surface>
		</collision>
		<!-- Visual -->
		<visual name="left_airbreak_visual">
			<pose frame=>0 0 0 0 0 0</pose>
			<geometry>
				<box>
					<size> 0.058634 0.391614 0.000598 </size>
	 			</box>
			</geometry>
			<material>
				<script>
					<name>Gazebo/Grey</name>
					<uri>file://media/materials/scripts/gazebo.material</uri>
				</script>
				<shader type='pixel'/>
          			<emissive>0 0 0 1</emissive>
			</material>
			<transparency>0</transparency>
        		<cast_shadows>1</cast_shadows>
		</visual>	</link>
	<joint name="left_airbreak_joint" type="revolute">
		<child>left_airbreak</child>
		<parent>base_link</parent>
		<pose frame=>0.025 -0.18 -0.005 0 0 0</pose>
		<axis>
			<xyz>0 1 0</xyz>
			<limit>
				<lower>-0.25</lower>
				<upper>0.25</upper>
			</limit>
			<dynamics>
				<spring_reference>0</spring_reference>
				<spring_stiffness>0</spring_stiffness>
				<damping>2</damping>
			</dynamics>
			<use_parent_model_frame>1</use_parent_model_frame>
		</axis>
		<physics>
			<ode>	
          			<implicit_spring_damper>1</implicit_spring_damper>
        		</ode>
      		</physics>
	</joint>
	<link name='queue_ag'>
	        <!-- Position -->
	        <pose frame=''>-1.26985 0.175395 0.33711 0.613889 -0.000186 3e-06</pose>
		<!-- Inertia -->
		<inertial>
			<pose frame=>0 0 0 0 -0 0</pose>
			<mass> 1.0e-11</mass>
			<inertia>
				<ixx>1.0e-09</ixx>
				<ixy>0</ixy>
				<ixz>0</ixz>
				<iyy>1.0e-09</iyy>
				<iyz>0</iyz>
				<izz>1.0e-09</izz>
			</inertia>
		</inertial>
		<!-- collision -->
		<collision name="queue_ag_colision">
			<laser_retro>0</laser_retro>
			<max_contacts>10</max_contacts>
			<pose frame=>0 0 0 0 0 0</pose>
			<geometry>
				<box>
					<size> 0.058634 0.391614 0.000598 </size>
				</box>
			</geometry>
			<surface>
				<friction>
					<ode>
						<mu>1</mu>
						<mu2>1</mu2>
						<fdir1>0 0 0</fdir1>
						<slip1>0</slip1>
						<slip2>0</slip2>
					</ode>
					<torsional>
						<coefficient>1</coefficient>
						<patch_radius>0</patch_radius>
						<surface_radius>0</surface_radius>
						<use_patch_radius>1</use_patch_radius>
						<ode>
							<slip>0</slip>
						</ode>
					</torsional>
				</friction>
				<bounce>
					<restitution_coefficient>0</restitution_coefficient>
					<threshold>1e+06</threshold>
				</bounce>
				<contact>
					<collide_without_contact>0</collide_without_contact>
					<collide_without_contact_bitmask>1</collide_without_contact_bitmask>
					<collide_bitmask>1</collide_bitmask>
					<ode>
						<soft_cfm>0</soft_cfm>
						<soft_erp>0.2</soft_erp>
						<kp>1e+13</kp>
						<kd>1</kd>
						<max_vel>0.01</max_vel>
						<min_depth>0</min_depth>
					</ode>
					<bullet>
						<split_impulse>1</split_impulse>
						<split_impulse_penetration_threshold>-0.01</split_impulse_penetration_threshold>
						<soft_cfm>0</soft_cfm>
						<soft_erp>0.2</soft_erp>
						<kp>1e+13</kp>
						<kd>1</kd>
					</bullet>
				</contact>
			</surface>
		</collision>
		<!-- Visual -->
		<visual name="queue_ag_visual">
			<pose frame=>0 0 0 0 0 0</pose>
			<geometry>
				<box>
					<size> 0.058634 0.391614 0.000598 </size>
	 			</box>
			</geometry>
			<material>
				<script>
					<name>Gazebo/Grey</name>
					<uri>file://media/materials/scripts/gazebo.material</uri>
				</script>
				<shader type='pixel'/>
          			<emissive>0 0 0 1</emissive>
			</material>
			<transparency>0</transparency>
        		<cast_shadows>1</cast_shadows>
		</visual>	</link>
	<joint name="queue_ag_joint" type="revolute">
		<child>queue_ag</child>
		<parent>base_link</parent>
		<pose frame=>0.03 0 0 0 0 0</pose>
		<axis>
			<xyz>0 1 0</xyz>
			<limit>
				<lower>-0.53</lower>
				<upper>0.53</upper>
			</limit>
			<dynamics>
				<spring_reference>0</spring_reference>
				<spring_stiffness>0</spring_stiffness>
				<damping>2</damping>
			</dynamics>
			<use_parent_model_frame>1</use_parent_model_frame>
		</axis>
		<physics>
			<ode>	
          			<implicit_spring_damper>1</implicit_spring_damper>
        		</ode>
      		</physics>
	</joint>
	<link name='queue_ad'>
	        <!-- Position -->
	        <pose frame=''>-1.26985 -0.175395 0.33711 -0.613889 -0.000186 3e-06</pose>
		<!-- Inertia -->
		<inertial>
			<pose frame=>0 0 0 0 -0 0</pose>
			<mass> 1.0e-11</mass>
			<inertia>
				<ixx>1.0e-09</ixx>
				<ixy>0</ixy>
				<ixz>0</ixz>
				<iyy>1.0e-09</iyy>
				<iyz>0</iyz>
				<izz>1.0e-09</izz>
			</inertia>
		</inertial>
		<!-- collision -->
		<collision name="queue_ad_colision">
			<laser_retro>0</laser_retro>
			<max_contacts>10</max_contacts>
			<pose frame=>0 0 0 0 0 0</pose>
			<geometry>
				<box>
					<size> 0.058634 0.391614 0.000598 </size>
				</box>
			</geometry>
			<surface>
				<friction>
					<ode>
						<mu>1</mu>
						<mu2>1</mu2>
						<fdir1>0 0 0</fdir1>
						<slip1>0</slip1>
						<slip2>0</slip2>
					</ode>
					<torsional>
						<coefficient>1</coefficient>
						<patch_radius>0</patch_radius>
						<surface_radius>0</surface_radius>
						<use_patch_radius>1</use_patch_radius>
						<ode>
							<slip>0</slip>
						</ode>
					</torsional>
				</friction>
				<bounce>
					<restitution_coefficient>0</restitution_coefficient>
					<threshold>1e+06</threshold>
				</bounce>
				<contact>
					<collide_without_contact>0</collide_without_contact>
					<collide_without_contact_bitmask>1</collide_without_contact_bitmask>
					<collide_bitmask>1</collide_bitmask>
					<ode>
						<soft_cfm>0</soft_cfm>
						<soft_erp>0.2</soft_erp>
						<kp>1e+13</kp>
						<kd>1</kd>
						<max_vel>0.01</max_vel>
						<min_depth>0</min_depth>
					</ode>
					<bullet>
						<split_impulse>1</split_impulse>
						<split_impulse_penetration_threshold>-0.01</split_impulse_penetration_threshold>
						<soft_cfm>0</soft_cfm>
						<soft_erp>0.2</soft_erp>
						<kp>1e+13</kp>
						<kd>1</kd>
					</bullet>
				</contact>
			</surface>
		</collision>
		<!-- Visual -->
		<visual name="queue_ad_visual">
			<pose frame=>0 0 0 0 0 0</pose>
			<geometry>
				<box>
					<size> 0.058634 0.391614 0.000598 </size>
	 			</box>
			</geometry>
			<material>
				<script>
					<name>Gazebo/Grey</name>
					<uri>file://media/materials/scripts/gazebo.material</uri>
				</script>
				<shader type='pixel'/>
          			<emissive>0 0 0 1</emissive>
			</material>
			<transparency>0</transparency>
        		<cast_shadows>1</cast_shadows>
		</visual>	</link>
	<joint name="queue_ad_joint" type="revolute">
		<child>queue_ad</child>
		<parent>base_link</parent>
		<pose frame=>0.03 0 0 0 0 0</pose>
		<axis>
			<xyz>0 1 0</xyz>
			<limit>
				<lower>-0.53</lower>
				<upper>0.53</upper>
			</limit>
			<dynamics>
				<spring_reference>0</spring_reference>
				<spring_stiffness>0</spring_stiffness>
				<damping>2</damping>
			</dynamics>
			<use_parent_model_frame>1</use_parent_model_frame>
		</axis>
		<physics>
			<ode>	
          			<implicit_spring_damper>1</implicit_spring_damper>
        		</ode>
      		</physics>
	</joint>	
	

			

	<link name="tilt_motor_0">
		<!-- Position -->
		<pose>  0.35 -0.4749999999999999 0.37 0 0 0 </pose>
		<!-- Inertia -->
		<inertial>
			<pose frame=>0 0 0 0 -0 0</pose>
			<mass> 0.005</mass>
			<inertia>
				<ixx>0.000166704</ixx>
				<ixy>0</ixy>
				<ixz>0</ixz>
				<iyy>0.000166704</iyy>
				<iyz>0</iyz>
				<izz>0.000166704</izz>
			</inertia>
		</inertial>		
		<!-- collision -->
		<collision name="tilt_motor_0_colision">
			<pose frame=>0 0 0 1.5707963267948966 0 0</pose>
			<geometry>
				<cylinder>
					<radius> 0.02 </radius>
					<length> 0.035 </length>
				</cylinder>
			</geometry>
			<surface>
				<contact>
					<ode>
						<min_depth>0.001</min_depth>
						<max_vel>0</max_vel>
					</ode>
				</contact>
				<friction>
					<ode/>
				</friction>
			</surface>
		</collision>
		<!-- Visual -->
		<visual name="tilt_motor_0_visual">
			<pose frame=>0 0 0 1.5707963267948966 0 0</pose>
			<geometry>
				<cylinder>
					<radius> 0.02 </radius>
					<length> 0.035 </length>
				</cylinder>
			</geometry>
			<material>
				<script>
					<name>Gazebo/DarkGrey</name>
					<uri>file://media/materials/scripts/gazebo.material</uri>
				</script>
			</material>
			</visual>		
		<gravity>1</gravity>
		<velocity_decay/>
	      </link>
	
	      
	<joint name="tilt_motor_0_joint" type="revolute">
		<child>tilt_motor_0</child>
		<parent>base_link</parent>
		<pose frame=>0 0 0 0 0 0</pose>
		<axis>
			<xyz>0 1 0</xyz>
			<limit>
				<lower>-3.3161255787892263</lower>
				<upper>3.3161255787892263</upper>
			</limit>
			<dynamics>
				<spring_reference>0</spring_reference>
				<spring_stiffness>0</spring_stiffness>
				<damping>0</damping>
			</dynamics>
			<use_parent_model_frame>1</use_parent_model_frame>
		</axis>
		
	</joint>
		
	<link name="rotor_0">
		<!-- Position -->
		<pose>  0.35 -0.4749999999999999 0.42 0 0 0 </pose>
		<!-- Inertia -->
		<inertial>
			<pose frame=>0 0 0 0 -0 0</pose>
			<mass> 0.005</mass>
			<inertia>
				<ixx>9.75e-07</ixx>
				<ixy>0</ixy>
				<ixz>0</ixz>
				<iyy>0.000166704</iyy>
				<iyz>0</iyz>
				<izz>0.000166704</izz>
			</inertia>
		</inertial>		
		<!-- collision -->
		<collision name="rotor_0_colision">
			<pose frame=>0 0 0 0 0 0</pose>
			<geometry>
				<cylinder>
					<radius> 0.128 </radius>
					<length> 0.005 </length>
				</cylinder>
			</geometry>
			<surface>
				<contact>
					<ode>
						<min_depth>0.001</min_depth>
						<max_vel>0</max_vel>
					</ode>
				</contact>
				<friction>
					<ode/>
				</friction>
			</surface>
		</collision>		
		<!-- Visual -->
		<visual name="rotor_0_visual">
			<pose frame=>0 0 0 0 0 0</pose>
			<geometry>
				<mesh>
					<scale>1 1 1</scale>
					<uri>model://rotors_description/meshes/iris_prop_ccw.dae</uri>
				</mesh>
			</geometry>
			<material>
				<script>
					<name>Gazebo/Blue</name>
					<uri>__default__</uri>
				</script>
				<shader type='pixel'/>
          			<emissive>0 0 0 1</emissive>
			</material>
			<transparency>0</transparency>
        		<cast_shadows>1</cast_shadows>
		</visual>		
		<gravity>1</gravity>
		<velocity_decay/>
	</link>
	<joint name="rotor_0_joint" type="revolute">
		<child>rotor_0</child>
		<parent>tilt_motor_0</parent>
		<pose frame=>0 0 0 0 0 0</pose>
		<axis>
			<xyz>0 0 1</xyz>
			<limit>
				<lower>-1.0e+16</lower>
				<upper>1.0e+16</upper>
			</limit>
			<dynamics>
				<spring_reference>0</spring_reference>
				<spring_stiffness>0</spring_stiffness>
				<damping>0</damping>
			</dynamics>
			<use_parent_model_frame>1</use_parent_model_frame>
		</axis>
		
	</joint>
	
		
			

	<link name="tilt_motor_1">
		<!-- Position -->
		<pose>  -0.3500000000000001 0.47499999999999987 0.37 0 0 0 </pose>
		<!-- Inertia -->
		<inertial>
			<pose frame=>0 0 0 0 -0 0</pose>
			<mass> 0.005</mass>
			<inertia>
				<ixx>0.000166704</ixx>
				<ixy>0</ixy>
				<ixz>0</ixz>
				<iyy>0.000166704</iyy>
				<iyz>0</iyz>
				<izz>0.000166704</izz>
			</inertia>
		</inertial>		
		<!-- collision -->
		<collision name="tilt_motor_1_colision">
			<pose frame=>0 0 0 1.5707963267948966 0 0</pose>
			<geometry>
				<cylinder>
					<radius> 0.02 </radius>
					<length> 0.035 </length>
				</cylinder>
			</geometry>
			<surface>
				<contact>
					<ode>
						<min_depth>0.001</min_depth>
						<max_vel>0</max_vel>
					</ode>
				</contact>
				<friction>
					<ode/>
				</friction>
			</surface>
		</collision>
		<!-- Visual -->
		<visual name="tilt_motor_1_visual">
			<pose frame=>0 0 0 1.5707963267948966 0 0</pose>
			<geometry>
				<cylinder>
					<radius> 0.02 </radius>
					<length> 0.035 </length>
				</cylinder>
			</geometry>
			<material>
				<script>
					<name>Gazebo/DarkGrey</name>
					<uri>file://media/materials/scripts/gazebo.material</uri>
				</script>
			</material>
			</visual>		
		<gravity>1</gravity>
		<velocity_decay/>
	      </link>
	
	      
	<joint name="tilt_motor_1_joint" type="revolute">
		<child>tilt_motor_1</child>
		<parent>base_link</parent>
		<pose frame=>0 0 0 0 0 0</pose>
		<axis>
			<xyz>0 -1 0</xyz>
			<limit>
				<lower>-3.3161255787892263</lower>
				<upper>3.3161255787892263</upper>
			</limit>
			<dynamics>
				<spring_reference>0</spring_reference>
				<spring_stiffness>0</spring_stiffness>
				<damping>0</damping>
			</dynamics>
			<use_parent_model_frame>1</use_parent_model_frame>
		</axis>
		
	</joint>
		
	<link name="rotor_1">
		<!-- Position -->
		<pose>  -0.3500000000000001 0.47499999999999987 0.31999999999999995 0 0 0 </pose>
		<!-- Inertia -->
		<inertial>
			<pose frame=>0 0 0 0 -0 0</pose>
			<mass> 0.005</mass>
			<inertia>
				<ixx>9.75e-07</ixx>
				<ixy>0</ixy>
				<ixz>0</ixz>
				<iyy>0.000166704</iyy>
				<iyz>0</iyz>
				<izz>0.000166704</izz>
			</inertia>
		</inertial>		
		<!-- collision -->
		<collision name="rotor_1_colision">
			<pose frame=>0 0 0 0 0 0</pose>
			<geometry>
				<cylinder>
					<radius> 0.128 </radius>
					<length> 0.005 </length>
				</cylinder>
			</geometry>
			<surface>
				<contact>
					<ode>
						<min_depth>0.001</min_depth>
						<max_vel>0</max_vel>
					</ode>
				</contact>
				<friction>
					<ode/>
				</friction>
			</surface>
		</collision>		
		<!-- Visual -->
		<visual name="rotor_1_visual">
			<pose frame=>0 0 0 0 0 0</pose>
			<geometry>
				<mesh>
					<scale>1 1 1</scale>
					<uri>model://rotors_description/meshes/iris_prop_ccw.dae</uri>
				</mesh>
			</geometry>
			<material>
				<script>
					<name>Gazebo/Blue</name>
					<uri>__default__</uri>
				</script>
				<shader type='pixel'/>
          			<emissive>0 0 0 1</emissive>
			</material>
			<transparency>0</transparency>
        		<cast_shadows>1</cast_shadows>
		</visual>		
		<gravity>1</gravity>
		<velocity_decay/>
	</link>
	<joint name="rotor_1_joint" type="revolute">
		<child>rotor_1</child>
		<parent>tilt_motor_1</parent>
		<pose frame=>0 0 0 0 0 0</pose>
		<axis>
			<xyz>0 0 1</xyz>
			<limit>
				<lower>-1.0e+16</lower>
				<upper>1.0e+16</upper>
			</limit>
			<dynamics>
				<spring_reference>0</spring_reference>
				<spring_stiffness>0</spring_stiffness>
				<damping>0</damping>
			</dynamics>
			<use_parent_model_frame>1</use_parent_model_frame>
		</axis>
		
	</joint>
	
		
			

	<link name="tilt_motor_2">
		<!-- Position -->
		<pose>  0.3499999999999999 0.47500000000000003 0.37 0 0 0 </pose>
		<!-- Inertia -->
		<inertial>
			<pose frame=>0 0 0 0 -0 0</pose>
			<mass> 0.005</mass>
			<inertia>
				<ixx>0.000166704</ixx>
				<ixy>0</ixy>
				<ixz>0</ixz>
				<iyy>0.000166704</iyy>
				<iyz>0</iyz>
				<izz>0.000166704</izz>
			</inertia>
		</inertial>		
		<!-- collision -->
		<collision name="tilt_motor_2_colision">
			<pose frame=>0 0 0 1.5707963267948966 0 0</pose>
			<geometry>
				<cylinder>
					<radius> 0.02 </radius>
					<length> 0.035 </length>
				</cylinder>
			</geometry>
			<surface>
				<contact>
					<ode>
						<min_depth>0.001</min_depth>
						<max_vel>0</max_vel>
					</ode>
				</contact>
				<friction>
					<ode/>
				</friction>
			</surface>
		</collision>
		<!-- Visual -->
		<visual name="tilt_motor_2_visual">
			<pose frame=>0 0 0 1.5707963267948966 0 0</pose>
			<geometry>
				<cylinder>
					<radius> 0.02 </radius>
					<length> 0.035 </length>
				</cylinder>
			</geometry>
			<material>
				<script>
					<name>Gazebo/DarkGrey</name>
					<uri>file://media/materials/scripts/gazebo.material</uri>
				</script>
			</material>
			</visual>		
		<gravity>1</gravity>
		<velocity_decay/>
	      </link>
	
	      
	<joint name="tilt_motor_2_joint" type="revolute">
		<child>tilt_motor_2</child>
		<parent>base_link</parent>
		<pose frame=>0 0 0 0 0 0</pose>
		<axis>
			<xyz>0 1 0</xyz>
			<limit>
				<lower>-3.3161255787892263</lower>
				<upper>3.3161255787892263</upper>
			</limit>
			<dynamics>
				<spring_reference>0</spring_reference>
				<spring_stiffness>0</spring_stiffness>
				<damping>0</damping>
			</dynamics>
			<use_parent_model_frame>1</use_parent_model_frame>
		</axis>
		
	</joint>
		<joint name="tilt_motor_2_gear_joint" type="gearbox">
		<child>tilt_motor_2</child>
		<parent>tilt_motor_1</parent>
		<gearbox_ratio>-1</gearbox_ratio>
		<gearbox_reference_body>base_link</gearbox_reference_body>
		<axis>
			<xyz>0 -1 0</xyz>
		</axis>
		<axis2>
			<xyz>0 -1 0</xyz>
		</axis2>
	</joint>		
	<link name="rotor_2">
		<!-- Position -->
		<pose>  0.3499999999999999 0.47500000000000003 0.42 0 0 0 </pose>
		<!-- Inertia -->
		<inertial>
			<pose frame=>0 0 0 0 -0 0</pose>
			<mass> 0.005</mass>
			<inertia>
				<ixx>9.75e-07</ixx>
				<ixy>0</ixy>
				<ixz>0</ixz>
				<iyy>0.000166704</iyy>
				<iyz>0</iyz>
				<izz>0.000166704</izz>
			</inertia>
		</inertial>		
		<!-- collision -->
		<collision name="rotor_2_colision">
			<pose frame=>0 0 0 0 0 0</pose>
			<geometry>
				<cylinder>
					<radius> 0.128 </radius>
					<length> 0.005 </length>
				</cylinder>
			</geometry>
			<surface>
				<contact>
					<ode>
						<min_depth>0.001</min_depth>
						<max_vel>0</max_vel>
					</ode>
				</contact>
				<friction>
					<ode/>
				</friction>
			</surface>
		</collision>		
		<!-- Visual -->
		<visual name="rotor_2_visual">
			<pose frame=>0 0 0 0 0 0</pose>
			<geometry>
				<mesh>
					<scale>1 1 1</scale>
					<uri>model://rotors_description/meshes/iris_prop_ccw.dae</uri>
				</mesh>
			</geometry>
			<material>
				<script>
					<name>Gazebo/DarkGrey</name>
					<uri>__default__</uri>
				</script>
				<shader type='pixel'/>
          			<emissive>0 0 0 1</emissive>
			</material>
			<transparency>0</transparency>
        		<cast_shadows>1</cast_shadows>
		</visual>		
		<gravity>1</gravity>
		<velocity_decay/>
	</link>
	<joint name="rotor_2_joint" type="revolute">
		<child>rotor_2</child>
		<parent>tilt_motor_2</parent>
		<pose frame=>0 0 0 0 0 0</pose>
		<axis>
			<xyz>0 0 1</xyz>
			<limit>
				<lower>-1.0e+16</lower>
				<upper>1.0e+16</upper>
			</limit>
			<dynamics>
				<spring_reference>0</spring_reference>
				<spring_stiffness>0</spring_stiffness>
				<damping>0</damping>
			</dynamics>
			<use_parent_model_frame>1</use_parent_model_frame>
		</axis>
		
	</joint>
	
		
			

	<link name="tilt_motor_3">
		<!-- Position -->
		<pose>  -0.35 -0.4749999999999999 0.37 0 0 0 </pose>
		<!-- Inertia -->
		<inertial>
			<pose frame=>0 0 0 0 -0 0</pose>
			<mass> 0.005</mass>
			<inertia>
				<ixx>0.000166704</ixx>
				<ixy>0</ixy>
				<ixz>0</ixz>
				<iyy>0.000166704</iyy>
				<iyz>0</iyz>
				<izz>0.000166704</izz>
			</inertia>
		</inertial>		
		<!-- collision -->
		<collision name="tilt_motor_3_colision">
			<pose frame=>0 0 0 1.5707963267948966 0 0</pose>
			<geometry>
				<cylinder>
					<radius> 0.02 </radius>
					<length> 0.035 </length>
				</cylinder>
			</geometry>
			<surface>
				<contact>
					<ode>
						<min_depth>0.001</min_depth>
						<max_vel>0</max_vel>
					</ode>
				</contact>
				<friction>
					<ode/>
				</friction>
			</surface>
		</collision>
		<!-- Visual -->
		<visual name="tilt_motor_3_visual">
			<pose frame=>0 0 0 1.5707963267948966 0 0</pose>
			<geometry>
				<cylinder>
					<radius> 0.02 </radius>
					<length> 0.035 </length>
				</cylinder>
			</geometry>
			<material>
				<script>
					<name>Gazebo/DarkGrey</name>
					<uri>file://media/materials/scripts/gazebo.material</uri>
				</script>
			</material>
			</visual>		
		<gravity>1</gravity>
		<velocity_decay/>
	      </link>
	
	      
	<joint name="tilt_motor_3_joint" type="revolute">
		<child>tilt_motor_3</child>
		<parent>base_link</parent>
		<pose frame=>0 0 0 0 0 0</pose>
		<axis>
			<xyz>0 -1 0</xyz>
			<limit>
				<lower>-3.3161255787892263</lower>
				<upper>3.3161255787892263</upper>
			</limit>
			<dynamics>
				<spring_reference>0</spring_reference>
				<spring_stiffness>0</spring_stiffness>
				<damping>0</damping>
			</dynamics>
			<use_parent_model_frame>1</use_parent_model_frame>
		</axis>
		
	</joint>
		<joint name="tilt_motor_3_gear_joint" type="gearbox">
		<child>tilt_motor_3</child>
		<parent>tilt_motor_0</parent>
		<gearbox_ratio>-1</gearbox_ratio>
		<gearbox_reference_body>base_link</gearbox_reference_body>
		<axis>
			<xyz>0 -1 0</xyz>
		</axis>
		<axis2>
			<xyz>0 -1 0</xyz>
		</axis2>
	</joint>		
	<link name="rotor_3">
		<!-- Position -->
		<pose>  -0.35 -0.4749999999999999 0.31999999999999995 0 0 0 </pose>
		<!-- Inertia -->
		<inertial>
			<pose frame=>0 0 0 0 -0 0</pose>
			<mass> 0.005</mass>
			<inertia>
				<ixx>9.75e-07</ixx>
				<ixy>0</ixy>
				<ixz>0</ixz>
				<iyy>0.000166704</iyy>
				<iyz>0</iyz>
				<izz>0.000166704</izz>
			</inertia>
		</inertial>		
		<!-- collision -->
		<collision name="rotor_3_colision">
			<pose frame=>0 0 0 0 0 0</pose>
			<geometry>
				<cylinder>
					<radius> 0.128 </radius>
					<length> 0.005 </length>
				</cylinder>
			</geometry>
			<surface>
				<contact>
					<ode>
						<min_depth>0.001</min_depth>
						<max_vel>0</max_vel>
					</ode>
				</contact>
				<friction>
					<ode/>
				</friction>
			</surface>
		</collision>		
		<!-- Visual -->
		<visual name="rotor_3_visual">
			<pose frame=>0 0 0 0 0 0</pose>
			<geometry>
				<mesh>
					<scale>1 1 1</scale>
					<uri>model://rotors_description/meshes/iris_prop_ccw.dae</uri>
				</mesh>
			</geometry>
			<material>
				<script>
					<name>Gazebo/DarkGrey</name>
					<uri>__default__</uri>
				</script>
				<shader type='pixel'/>
          			<emissive>0 0 0 1</emissive>
			</material>
			<transparency>0</transparency>
        		<cast_shadows>1</cast_shadows>
		</visual>		
		<gravity>1</gravity>
		<velocity_decay/>
	</link>
	<joint name="rotor_3_joint" type="revolute">
		<child>rotor_3</child>
		<parent>tilt_motor_3</parent>
		<pose frame=>0 0 0 0 0 0</pose>
		<axis>
			<xyz>0 0 1</xyz>
			<limit>
				<lower>-1.0e+16</lower>
				<upper>1.0e+16</upper>
			</limit>
			<dynamics>
				<spring_reference>0</spring_reference>
				<spring_stiffness>0</spring_stiffness>
				<damping>0</damping>
			</dynamics>
			<use_parent_model_frame>1</use_parent_model_frame>
		</axis>
		
	</joint>
	
		
		
	<plugin name='rosbag' filename='libgazebo_multirotor_base_plugin.so'>
		<robotNamespace/>
		<linkName>base_link</linkName>
		<rotorVelocitySlowdownSim>10</rotorVelocitySlowdownSim>
	</plugin>
	
					
	<plugin name='motor_0_model' filename='libgazebo_motor_model.so'>
		<robotNamespace/>
		<jointName>			rotor_0_joint			</jointName>
		<linkName>			rotor_0			</linkName>
		<turningDirection>		ccw				</turningDirection>
		<timeConstantUp>		0.0125				</timeConstantUp>
		<timeConstantDown>		0.025				</timeConstantDown>
		<maxRotVelocity>		1100				</maxRotVelocity>
		<motorConstant>		0.00011			</motorConstant>
		<momentConstant>		0.045				</momentConstant>
		<commandSubTopic>		/gazebo/command/motor_speed	</commandSubTopic>
		<motorNumber>			0				</motorNumber>
		<rotorDragCoefficient>		0.000175			</rotorDragCoefficient>
		<rollingMomentCoefficient>	1.0e-06			</rollingMomentCoefficient>
		<motorSpeedPubTopic>		/motor_speed/0			</motorSpeedPubTopic>
		<rotorVelocitySlowdownSim>	10				</rotorVelocitySlowdownSim>
	</plugin>
		
					
	<plugin name='motor_1_model' filename='libgazebo_motor_model.so'>
		<robotNamespace/>
		<jointName>			rotor_1_joint			</jointName>
		<linkName>			rotor_1			</linkName>
		<turningDirection>		ccw				</turningDirection>
		<timeConstantUp>		0.0125				</timeConstantUp>
		<timeConstantDown>		0.025				</timeConstantDown>
		<maxRotVelocity>		1100				</maxRotVelocity>
		<motorConstant>		0.00011			</motorConstant>
		<momentConstant>		0.045				</momentConstant>
		<commandSubTopic>		/gazebo/command/motor_speed	</commandSubTopic>
		<motorNumber>			1				</motorNumber>
		<rotorDragCoefficient>		0.000175			</rotorDragCoefficient>
		<rollingMomentCoefficient>	1.0e-06			</rollingMomentCoefficient>
		<motorSpeedPubTopic>		/motor_speed/1			</motorSpeedPubTopic>
		<rotorVelocitySlowdownSim>	10				</rotorVelocitySlowdownSim>
	</plugin>
		
					
	<plugin name='motor_2_model' filename='libgazebo_motor_model.so'>
		<robotNamespace/>
		<jointName>			rotor_2_joint			</jointName>
		<linkName>			rotor_2			</linkName>
		<turningDirection>		cw				</turningDirection>
		<timeConstantUp>		0.0125				</timeConstantUp>
		<timeConstantDown>		0.025				</timeConstantDown>
		<maxRotVelocity>		1100				</maxRotVelocity>
		<motorConstant>		0.00011			</motorConstant>
		<momentConstant>		0.045				</momentConstant>
		<commandSubTopic>		/gazebo/command/motor_speed	</commandSubTopic>
		<motorNumber>			2				</motorNumber>
		<rotorDragCoefficient>		0.000175			</rotorDragCoefficient>
		<rollingMomentCoefficient>	1.0e-06			</rollingMomentCoefficient>
		<motorSpeedPubTopic>		/motor_speed/2			</motorSpeedPubTopic>
		<rotorVelocitySlowdownSim>	10				</rotorVelocitySlowdownSim>
	</plugin>
		
					
	<plugin name='motor_3_model' filename='libgazebo_motor_model.so'>
		<robotNamespace/>
		<jointName>			rotor_3_joint			</jointName>
		<linkName>			rotor_3			</linkName>
		<turningDirection>		cw				</turningDirection>
		<timeConstantUp>		0.0125				</timeConstantUp>
		<timeConstantDown>		0.025				</timeConstantDown>
		<maxRotVelocity>		1100				</maxRotVelocity>
		<motorConstant>		0.00011			</motorConstant>
		<momentConstant>		0.045				</momentConstant>
		<commandSubTopic>		/gazebo/command/motor_speed	</commandSubTopic>
		<motorNumber>			3				</motorNumber>
		<rotorDragCoefficient>		0.000175			</rotorDragCoefficient>
		<rollingMomentCoefficient>	1.0e-06			</rollingMomentCoefficient>
		<motorSpeedPubTopic>		/motor_speed/3			</motorSpeedPubTopic>
		<rotorVelocitySlowdownSim>	10				</rotorVelocitySlowdownSim>
	</plugin>
		
	
	<model name='gps0'>
	<link name='link'>
	<pose frame=''>0 0 0 0 -0 0</pose>
	<inertial>
	  <pose frame=''>0 0 0 0 -0 0</pose>
	  <mass>0.01</mass>
	  <inertia>
	    <ixx>2.1733e-06</ixx>
	    <ixy>0</ixy>
	    <ixz>0</ixz>
	    <iyy>2.1733e-06</iyy>
	    <iyz>0</iyz>
	    <izz>1.8e-07</izz>
	  </inertia>
	</inertial>
	<visual name='visual'>
	  <geometry>
	    <cylinder>
	      <radius>0.01</radius>
	      <length>0.002</length>
	    </cylinder>
	  </geometry>
	  <material>
	    <script>
	      <name>Gazebo/Black</name>
	      <uri>__default__</uri>
	    </script>
	  </material>
	</visual>
	<sensor name='gps' type='gps'>
	  <pose frame=''>0 0 0 0 -0 0</pose>
	  <plugin name='gps_plugin' filename='libgazebo_gps_plugin.so'>
	    <robotNamespace/>
	    <gpsNoise>1</gpsNoise>
	    <gpsXYRandomWalk>2.0</gpsXYRandomWalk>
	    <gpsZRandomWalk>4.0</gpsZRandomWalk>
	    <gpsXYNoiseDensity>0.0002</gpsXYNoiseDensity>
	    <gpsZNoiseDensity>0.0004</gpsZNoiseDensity>
	    <gpsVXYNoiseDensity>0.2</gpsVXYNoiseDensity>
	    <gpsVZNoiseDensity>0.4</gpsVZNoiseDensity>
	  </plugin>
	</sensor>
	</link>
	</model>
	<joint name='gps0_joint' type='fixed'>
	<parent>base_link</parent>
	<child>gps0::link</child>
	</joint>
	<plugin name='groundtruth_plugin' filename='libgazebo_groundtruth_plugin.so'>
	<robotNamespace/>
	</plugin>
	<plugin name='magnetometer_plugin' filename='libgazebo_magnetometer_plugin.so'>
		<robotNamespace/>
		<pubRate>100</pubRate>
		<noiseDensity>0.0004</noiseDensity>
		<randomWalk>6.4e-06</randomWalk>
		<biasCorrelationTime>600</biasCorrelationTime>
		<magTopic>/mag</magTopic>
	</plugin>
	<plugin name='barometer_plugin' filename='libgazebo_barometer_plugin.so'>
		<robotNamespace/>
		<pubRate>50</pubRate>
		<baroTopic>/baro</baroTopic>
	</plugin>
	
	<plugin name='mavlink_interface' filename='libgazebo_mavlink_interface.so'>
		<robotNamespace/>
		<imuSubTopic>/imu</imuSubTopic>
		<gpsSubTopic>/gps</gpsSubTopic>
		<magSubTopic>/mag</magSubTopic>
		<baroSubTopic>/baro</baroSubTopic>
		<mavlink_addr>INADDR_ANY</mavlink_addr>
		<mavlink_udp_port>14560</mavlink_udp_port>
		<mavlink_tcp_port>4560</mavlink_tcp_port>
		<serialEnabled>0</serialEnabled>
		<serialDevice>/dev/ttyACM0</serialDevice>
		<baudRate>921600</baudRate>
		<qgc_addr>INADDR_ANY</qgc_addr>
		<qgc_udp_port>14550</qgc_udp_port>
		<sdk_addr>INADDR_ANY</sdk_addr>
		<sdk_udp_port>14540</sdk_udp_port>
		<hil_mode>0</hil_mode>
		<hil_state_level>0</hil_state_level>
		<vehicle_is_tailsitter>0</vehicle_is_tailsitter>
		<send_vision_estimation>0</send_vision_estimation>
		<send_odometry>1</send_odometry>
		<enable_lockstep>1</enable_lockstep>
		<use_tcp>1</use_tcp>
		<motorSpeedCommandPubTopic>/gazebo/command/motor_speed</motorSpeedCommandPubTopic>
		<control_channels>
			<channel name='rotor0'>
	                        <input_index>0</input_index>
				<input_scaling>1379.5</input_scaling>
				<input_offset>0</input_offset>
				<zero_position_disarmed>0 </zero_position_disarmed>
				<zero_position_armed>-89.0</zero_position_armed>
				<joint_name>rotor_0_joint</joint_name>
				<joint_control_type>velocity</joint_control_type>
			</channel>
	
			<channel name='rotor1'>
	                        <input_index>1</input_index>
				<input_scaling>1379.5</input_scaling>
				<input_offset>0</input_offset>
				<zero_position_disarmed>0 </zero_position_disarmed>
				<zero_position_armed>-89.0</zero_position_armed>
				<joint_name>rotor_1_joint</joint_name>
				<joint_control_type>velocity</joint_control_type>
			</channel>
	
			<channel name='rotor2'>
	                        <input_index>2</input_index>
				<input_scaling>1379.5</input_scaling>
				<input_offset>0</input_offset>
				<zero_position_disarmed>0 </zero_position_disarmed>
				<zero_position_armed>-89.0</zero_position_armed>
				<joint_name>rotor_2_joint</joint_name>
				<joint_control_type>velocity</joint_control_type>
			</channel>
	
			<channel name='rotor3'>
	                        <input_index>3</input_index>
				<input_scaling>1379.5</input_scaling>
				<input_offset>0</input_offset>
				<zero_position_disarmed>0 </zero_position_disarmed>
				<zero_position_armed>-89.0</zero_position_armed>
				<joint_name>rotor_3_joint</joint_name>
				<joint_control_type>velocity</joint_control_type>
			</channel>
	
					
						
	                <channel name="tilt_motor_0">
			        <input_index>            4                  </input_index>
				<input_scaling>  0.8726646259971649 </input_scaling>
				<input_offset>           0                  </input_offset>
				<zero_position_disarmed> 0                  </zero_position_disarmed>
				<zero_position_armed>    0.8203047484373348 </zero_position_armed>
				<joint_control_type>     position           </joint_control_type>
				<joint_name>             tilt_motor_0_joint </joint_name>
				 <joint_control_pid>
				   <p>0.1</p>
				   <i>0</i>
				   <d>0.01</d>
				   <iMax>0.0</iMax>
				   <iMin>0.0</iMin>
				   <cmdMax>1.5707963267948966</cmdMax>
				   <cmdMin>-1.5707963267948966</cmdMin>
				 </joint_control_pid>
			</channel>
						
	                <channel name="tilt_motor_1">
			        <input_index>            5                  </input_index>
				<input_scaling>  0.8726646259971649 </input_scaling>
				<input_offset>           0                  </input_offset>
				<zero_position_disarmed> 0                  </zero_position_disarmed>
				<zero_position_armed>    -0.7155849933176751 </zero_position_armed>
				<joint_control_type>     position           </joint_control_type>
				<joint_name>             tilt_motor_1_joint </joint_name>
				 <joint_control_pid>
				   <p>0.1</p>
				   <i>0</i>
				   <d>0.01</d>
				   <iMax>0.0</iMax>
				   <iMin>0.0</iMin>
				   <cmdMax>1.5707963267948966</cmdMax>
				   <cmdMin>-1.5707963267948966</cmdMin>
				 </joint_control_pid>
			</channel>
					
		</control_channels>
	</plugin>
	
	<static>0</static>
	<plugin name='rotors_gazebo_imu_plugin' filename='libgazebo_imu_plugin.so'>
		<robotNamespace/>
		<linkName>/imu_link</linkName>
		<imuTopic>/imu</imuTopic>
		<gyroscopeNoiseDensity>0.00018665</gyroscopeNoiseDensity>
		<gyroscopeRandomWalk>3.8785e-05</gyroscopeRandomWalk>
		<gyroscopeBiasCorrelationTime>1000.0</gyroscopeBiasCorrelationTime>
		<gyroscopeTurnOnBiasSigma>0.0087</gyroscopeTurnOnBiasSigma>
		<accelerometerNoiseDensity>0.00186</accelerometerNoiseDensity>
		<accelerometerRandomWalk>0.006</accelerometerRandomWalk>
		<accelerometerBiasCorrelationTime>300.0</accelerometerBiasCorrelationTime>
		<accelerometerTurnOnBiasSigma>0.196</accelerometerTurnOnBiasSigma>
	</plugin>
	
</model>
</sdf>
